<?xml version="1.0" encoding="utf-8"?>

<robot name="yahboomcar" xmlns:xacro="http://ros.org/wiki/xacro">
    <!-- Links -->
    <link name="base_footprint" />
    <link name="imu_link" />

    <link name="base_link">
        <inertial>
            <origin
                xyz="-0.012469 0.00028284 0.19831"
                rpy="0 0 0" />
            <mass
                value="0.59442" />
            <inertia
                ixx="0.013156"
                ixy="2.7714E-07"
                ixz="-3.4181E-07"
                iyy="0.014041"
                iyz="-3.1438E-08"
                izz="0.0020177" />
        </inertial>
        <visual>
            <origin
                xyz="0 0 0"
                rpy="0 0 0" />
            <geometry>
                <mesh
                    filename="package://yahboomcar_description/meshes/base_link.STL" />
            </geometry>
            <material
                name="">
                <color
                    rgba="0 1 0 1" />
            </material>
        </visual>
        <collision>
            <origin
                xyz="0 0 0"
                rpy="0 0 0" />
            <geometry>
                <mesh
                    filename="package://yahboomcar_description/meshes/base_link.STL" />
            </geometry>
        </collision>
    </link>

    <link
        name="front_left_wheel">
        <inertial>
            <origin
                xyz="1.2586E-10 -1.92E-10 0.018702"
                rpy="0 0 0" />
            <mass
                value="0.11248" />
            <inertia
                ixx="1.9114E-05"
                ixy="5.7267E-16"
                ixz="-9.0393E-15"
                iyy="1.9114E-05"
                iyz="1.3117E-15"
                izz="2.2116E-05" />
        </inertial>
        <visual>
            <origin
                xyz="0 0 0"
                rpy="0 0 0" />
            <geometry>
                <mesh
                    filename="package://yahboomcar_description/meshes/front_left_wheel.STL" />
            </geometry>
            <material
                name="">
                <color
                    rgba="0 0 0 1" />
            </material>
        </visual>
        <collision>
            <origin
                xyz="0 0 0"
                rpy="0 0 0" />
            <geometry>
                <cylinder lenght="0.05" radius="0.05365"/>
            </geometry>
        </collision>
    </link>

    <link
        name="front_right_wheel">
        <inertial>
            <origin
                xyz="1.3127E-10 2.0431E-10 0.018702"
                rpy="0 0 0" />
            <mass
                value="0.11248" />
            <inertia
                ixx="1.9114E-05"
                ixy="-6.8229E-16"
                ixz="-7.3242E-15"
                iyy="1.9114E-05"
                iyz="-8.5095E-15"
                izz="2.2116E-05" />
        </inertial>
        <visual>
            <origin
                xyz="0 0 0"
                rpy="0 0 0" />
            <geometry>
                <mesh
                    filename="package://yahboomcar_description/meshes/front_right_wheel.STL" />
            </geometry>
            <material
                name="">
                <color
                    rgba="0 0 0 1" />
            </material>
        </visual>
        <collision>
            <origin
                xyz="0 0 0"
                rpy="0 0 0" />
            <geometry>
                <cylinder lenght="0.05" radius="0.05365"/>
            </geometry>
        </collision>
    </link>

    <link
        name="back_left_wheel">
        <inertial>
            <origin
                xyz="1.3127E-10 -2.0431E-10 0.018798"
                rpy="0 0 0" />
            <mass
                value="0.11248" />
            <inertia
                ixx="1.9114E-05"
                ixy="6.8228E-16"
                ixz="7.3242E-15"
                iyy="1.9114E-05"
                iyz="-8.5095E-15"
                izz="2.2116E-05" />
        </inertial>
        <visual>
            <origin
                xyz="0 0 0"
                rpy="0 0 0" />
            <geometry>
                <mesh
                    filename="package://yahboomcar_description/meshes/back_left_wheel.STL" />
            </geometry>
            <material
                name="">
                <color
                    rgba="0 0 0 1" />
            </material>
        </visual>
        <collision>
            <origin
                xyz="0 0 0"
                rpy="0  0 0" />
            <geometry>
                <cylinder lenght="0.05" radius="0.05365"/>
            </geometry>
        </collision>
    </link>

    <link
        name="back_right_wheel">
        <inertial>
            <origin
                xyz="1.2586E-10 1.92E-10 0.018798"
                rpy="0 0 0" />
            <mass
                value="0.11248" />
            <inertia
                ixx="1.9114E-05"
                ixy="-5.7266E-16"
                ixz="9.0393E-15"
                iyy="1.9114E-05"
                iyz="1.3117E-15"
                izz="2.2116E-05" />
        </inertial>
        <visual>
            <origin
                xyz="0 0 0"
                rpy="0 0 0" />
            <geometry>
                <mesh
                    filename="package://yahboomcar_description/meshes/back_right_wheel.STL" />
            </geometry>
            <material
                name="">
                <color
                    rgba="0 0 0 1" />
            </material>
        </visual>
        <collision>
            <origin
                xyz="0 0 0"
                rpy="0 0 0" />
            <geometry>
                <cylinder lenght="0.05" radius="0.05365"/>
            </geometry>
        </collision>
    </link>

    <link name="laser_link">
        <inertial>
            <origin
              xyz="0.00070942 0.0008187 0.013068"
              rpy="0 0 0" />
            <mass
              value="0.045513" />
            <inertia
              ixx="8.6093E-06"
              ixy="1.7259E-07"
              ixz="6.5083E-09"
              iyy="8.4939E-06"
              iyz="5.3304E-08"
              izz="1.0141E-05" />
          </inertial>
          <visual>
            <origin
              xyz="0 0 0"
              rpy="0 0 0" />
            <geometry>
              <mesh
                filename="package://yahboomcar_description/meshes/laser_link.STL" />
            </geometry>
            <material
              name="">
              <color
                rgba="0.74902 0.74902 0.74902 1" />
            </material>
          </visual>
          <collision>
            <origin
              xyz="0 0 0"
              rpy="0 0 0" />
            <geometry>
              <mesh
                filename="package://yahboomcar_description/meshes/laser_link.STL" />
            </geometry>
          </collision>
    </link>

    <link name="camera_base">
        <inertial>
            <origin
                xyz="-0.0093539 0.0010953 0.058127"
                rpy="0 0 0" />
            <mass
                value="0.034908" />
            <inertia
                ixx="2.2397E-05"
                ixy="-2.3526E-07"
                ixz="6.9057E-07"
                iyy="1.1978E-05"
                iyz="5.949E-07"
                izz="1.5217E-05" />
        </inertial>
        <visual>
            <origin
                xyz="0 0 0"
                rpy="0 0 0" />
            <geometry>
                <mesh
                filename="package://yahboomcar_description/meshes/camera_base.STL" />
            </geometry>
            <material
                name="">
                <color
                rgba="0.74902 0.74902 0.74902 1" />
            </material>
        </visual>
        <collision>
            <origin
                xyz="0 0 0"
                rpy="0 0 0" />
            <geometry>
                <mesh
                filename="package://yahboomcar_description/meshes/camera_base.STL" />
            </geometry>
        </collision>
    </link>

    <link name="camera_link">
        <inertial>
            <origin
                xyz="0.010756 -0.00084697 -0.0013917"
                rpy="0 0 0" />
            <mass
                value="0.050094" />
            <inertia
                ixx="2.2677E-05"
                ixy="-9.3994E-09"
                ixz="3.4279E-08"
                iyy="1.3345E-05"
                iyz="-1.7328E-07"
                izz="1.2266E-05" />
        </inertial>
        <visual>
            <origin
                xyz="0 0 0"
                rpy="0 0 0" />
            <geometry>
                <mesh
                filename="package://yahboomcar_description/meshes/camera_link.STL" />
            </geometry>
            <material
                name="">
                <color
                rgba="0.79216 0.81961 0.93333 1" />
            </material>
        </visual>
        <collision>
            <origin
                xyz="0 0 0"
                rpy="0 0 0" />
            <geometry>
                <mesh
                filename="package://yahboomcar_description/meshes/camera_link.STL" />
            </geometry>
        </collision>
    </link>

    <!-- Joints-->
    <joint name="base_joint" type="fixed">
        <parent link="base_footprint" />
        <child link="base_link" />
        <origin xyz="0.0 0.0 0.076" rpy="0 0 0" />
    </joint>

    <joint
        name="front_left_joint"
        type="continuous">
        <origin
            xyz="0.11797 0.084101 -0.0389"
            rpy="-1.5708 0 0" />
        <parent
            link="base_link" />
        <child
            link="front_left_wheel" />
        <axis
            xyz="0 0 1" />
    </joint>

    <joint
        name="front_right_joint"
        type="continuous">
        <origin
            xyz="0.11797 -0.084099 -0.0389"
            rpy="1.5708 0 0" />
        <parent
            link="base_link" />
        <child
            link="front_right_wheel" />
        <axis
            xyz="0 0 1" />
    </joint>

    <joint
        name="back_left_joint"
        type="continuous">
        <origin
            xyz="-0.10203 0.084101 -0.0395"
            rpy="-1.5708 0 0" />
        <parent
            link="base_link" />
        <child
            link="back_left_wheel" />
        <axis
            xyz="0 0 1" />
    </joint>

    <joint
        name="back_right_joint"
        type="continuous">
        <origin
            xyz="-0.10203 -0.084099 -0.0395"
            rpy="1.5708 0 0" />
        <parent
            link="base_link" />
        <child
            link="back_right_wheel" />
        <axis
            xyz="0 0 1" />
    </joint>

    <joint name="imu_joint" type="fixed">
        <parent link="base_link"/>
        <child link="imu_link"/>
        <origin xyz="0 0 0" rpy="0 0 0"/>
    </joint>

    <joint name="laser_joint" type="fixed">
            <origin
                xyz="0.11596 -0.0019383 0"
                rpy="0 0 0" />
            <parent link="base_link" />
            <child link="laser_link" />
            <axis
                xyz="0 0 1" />
        </joint>

</robot>
