<?xml version="1.0"?>
<robot name="omnimate"
    xmlns:xacro="http://www.ros.org/wiki/xacro">
    <!-- Include files-->
    <xacro:include filename="$(find omnimate_description)/urdf/common_properties.xacro"/>
    <!-- <xacro:include filename="$(find omnimate_description)/urdf/intel_realsense_l515/_l515.urdf.xacro"/> -->

    <!-- Links and joints -->
    <link name="base_footprint"/>

    <joint name="base_joint" type="fixed">
        <origin xyz="0 0 0.07" rpy="0 0 0"/>
        <parent link="base_footprint"/>
        <child link="base_link"/>
        <axis xyz="0 0 1"/>
    </joint>

    <link name="imu_link"/>

    <joint name="imu_joint" type="fixed">
        <origin xyz="0 0 0.07" rpy="0 0 0"/>
        <parent link="base_footprint"/>
        <child link="imu_link"/>
        <axis xyz="0 0 1"/>
    </joint>

    <link name="base_link">
        <inertial>
            <origin xyz="-0.012469 0.00028284 0.19831" rpy="0 0 0"/>
            <mass value="0.59442"/>
            <inertia ixx="0.013156" ixy="2.7714E-07" ixz="-3.4181E-07" iyy="0.014041" iyz="-3.1438E-08" izz="0.0020177"/>
        </inertial>

        <visual>
            <origin xyz="0 0 0" rpy="0 0 0"/>
            <geometry>
                <mesh filename="package://omnimate_description/meshes/base_link.STL"/>
            </geometry>
            <material name="green"/>
        </visual>

        <collision>
            <origin xyz="0 0 0" rpy="0 0 0"/>
            <geometry>
                <mesh filename="package://omnimate_description/meshes/base_link.STL"/>
            </geometry>
        </collision>
    </link>

    <link name="front_left_wheel">
        <inertial>
            <origin xyz="1.2586E-10 -1.92E-10 0.018702" rpy="0 0 0"/>
            <mass value="0.11248"/>
            <inertia ixx="1.9114E-05" ixy="5.7267E-16" ixz="-9.0393E-15" iyy="1.9114E-05" iyz="1.3117E-15" izz="2.2116E-05" />
        </inertial>

        <visual>
            <origin xyz="0 0 0" rpy="0 0 0"/>
            <geometry>
                <mesh filename="package://omnimate_description/meshes/front_left_wheel.STL"/>
            </geometry>
            <material name="black"/>
        </visual>

        <collision>
            <origin xyz="0 0 0" rpy="0 0 0"/>
            <geometry>
                <cylinder length="0.05" radius="0.05365"/>
            </geometry>
        </collision>
    </link>

    <joint name="front_left_joint" type="continuous">
        <origin xyz="0.11797 0.084101 -0.0389" rpy="-1.5708 0 0"/>
        <parent link="base_link"/>
        <child link="front_left_wheel"/>
        <axis xyz="0 0 1" rpy="0 0 0"/>
        <limit effort="100" velocity="1"/>
    </joint>

    <link name="front_right_wheel">
        <inertial>
            <origin xyz="1.3127E-10 2.0431E-10 0.018702" rpy="0 0 0"/>
            <mass value="0.11248"/>
            <inertia ixx="1.9114E-05" ixy="-6.8229E-16" ixz="-7.3242E-15" iyy="1.9114E-05" iyz="-8.5095E-15" izz="2.2116E-05"/>
        </inertial>

        <visual>
            <origin xyz="0 0 0" rpy="0 0 0"/>
            <geometry>
                <mesh filename="package://omnimate_description/meshes/front_right_wheel.STL"/>
            </geometry>
            <material name="black"/>
        </visual>

        <collision>
            <origin xyz="0 0 0" rpy="0 0 0"/>
            <geometry>
                <cylinder length="0.05" radius="0.05365"/>
            </geometry>
        </collision>
    </link>

    <joint name="front_right_joint" type="continuous">
        <origin xyz="0.11797 -0.084099 -0.0389" rpy="1.5708 0 0"/>
        <parent link="base_link"/>
        <child link="front_right_wheel"/>
        <axis xyz="0 0 1" rpy="0 0 0"/>
        <limit effort="100" velocity="1"/>
    </joint>

    <link name="back_left_wheel">
        <inertial>
            <origin xyz="1.3127E-10 -2.0431E-10 0.018798" rpy="0 0 0"/>
            <mass value="0.11248"/>
            <inertia ixx="1.9114E-05" ixy="6.8228E-16" ixz="7.3242E-15" iyy="1.9114E-05" iyz="-8.5095E-15" izz="2.2116E-05"/>
        </inertial>

        <visual>
            <origin xyz="0 0 0" rpy="0 0 0"/>
            <geometry>
                <mesh filename="package://omnimate_description/meshes/back_left_wheel.STL"/>
            </geometry>
            <material name="black"/>
        </visual>

        <collision>
            <origin xyz="0 0 0" rpy="0  0 0" />
            <geometry>
                <cylinder length="0.05" radius="0.05365"/>
            </geometry>
        </collision>
    </link>

    <joint name="back_left_joint" type="continuous">
        <origin xyz="-0.10203 0.084101 -0.0395" rpy="-1.5708 0 0"/>
        <parent link="base_link"/>
        <child link="back_left_wheel"/>
        <axis xyz="0 0 1" rpy="0 0 0"/>
        <limit effort="100" velocity="1"/>
    </joint>

    <link name="back_right_wheel">
        <inertial>
            <origin xyz="1.2586E-10 1.92E-10 0.018798" rpy="0 0 0"/>
            <mass value="0.11248"/>
            <inertia ixx="1.9114E-05" ixy="-5.7266E-16" ixz="9.0393E-15" iyy="1.9114E-05" iyz="1.3117E-15" izz="2.2116E-05"/>
        </inertial>

        <visual>
            <origin xyz="0 0 0" rpy="0 0 0"/>
            <geometry>
                <mesh filename="package://omnimate_description/meshes/back_right_wheel.STL"/>
            </geometry>
            <material name="black"/>
        </visual>

        <collision>
            <origin xyz="0 0 0" rpy="0 0 0"/>
            <geometry>
                <cylinder length="0.05" radius="0.05365"/>
            </geometry>
        </collision>
    </link>

    <joint name="back_right_joint" type="continuous">
        <origin xyz="-0.10203 -0.084099 -0.0395" rpy="1.5708 0 0"/>
        <parent link="base_link"/>
        <child link="back_right_wheel"/>
        <axis xyz="0 0 1" rpy="0 0 0"/>
        <limit effort="100" velocity="1"/>
    </joint>

    <link name="camera_base">
        <inertial>
            <origin xyz="-0.0093539 0.0010953 0.058127" rpy="0 0 0"/>
            <mass value="0.034908"/>
            <inertia ixx="2.2397E-05" ixy="-2.3526E-07" ixz="6.9057E-07" iyy="1.1978E-05" iyz="5.949E-07" izz="1.5217E-05"/>
        </inertial>

        <visual>
            <origin xyz="0 0 0" rpy="0 0 0"/>
            <geometry>
                <mesh filename="package://omnimate_description/meshes/camera_base.STL"/>
            </geometry>
            <material name="purple"/>
        </visual>

        <collision>
            <origin xyz="0 0 0" rpy="0 0 0"/>
            <geometry>
                <mesh filename="package://omnimate_description/meshes/camera_base.STL"/>
            </geometry>
        </collision>
    </link>

    <joint name="camera_base_joint" type="fixed">
        <origin xyz="0.14057 0 0.066" rpy="0 0 0"/>
        <parent link="base_link"/>
        <child link="camera_base"/>
        <axis xyz="0 0 0"/>
    </joint>

    <link name="camera_reference_link"/>

    <joint name="camera_reference_joint" type="fixed">
        <!--<origin xyz="-0.020646 -0.0011633 0.088297" rpy="1.5708 0 0"/>-->
        <origin xyz="-0.006 -0.0011633 0.057797" rpy="0 0 0"/>
        <parent link="camera_base"/>
        <child link="camera_reference_link"/>
        <axis xyz="0 0 0"/>
    </joint>

    <joint name="camera_reference_joint" type="fixed">
        <!--<origin xyz="-0.020646 -0.0011633 0.088297" rpy="1.5708 0 0"/>-->
        <origin xyz="-0.006 -0.0011633 0.057797" rpy="0 0 0"/>
        <parent link="camera_base"/>
        <child link="camera_reference_link"/>
        <axis xyz="0 0 0"/>
    </joint>

    <link name="base_scan">
        <inertial>
            <origin xyz="0.00070942 0.0008187 0.013068" rpy="0 0 0"/>
            <mass value="0.045513" />
            <inertia ixx="8.6093E-06" ixy="1.7259E-07" ixz="6.5083E-09" iyy="8.4939E-06" iyz="5.3304E-08" izz="1.0141E-05"/>
        </inertial>

        <visual>
            <origin xyz="0 0 0" rpy="0 0 0"/>
            <geometry>
                <mesh filename="package://omnimate_description/meshes/laser_link.STL"/>
            </geometry>
            <material name="black"/>
        </visual>

        <collision>
            <origin xyz="0 0 0" rpy="0 0 0"/>
            <geometry>
                <mesh filename="package://omnimate_description/meshes/laser_link.STL"/>
            </geometry>
        </collision>
    </link>

    <joint name="laser_joint" type="fixed">
        <origin xyz="0.11596 -0.0019383 0" rpy="0 0 0"/>
        <parent link="base_link"/>
        <child link="base_scan"/>
        <axis xyz="0 0 1"/>
    </joint>

    <!-- <xacro:sensor_l515 name="camera" topics_ns="camera" parent="camera_reference_link" use_nominal_extrinsics="true" publish_pointcloud="true" add_plug="false" use_mesh="true">
        <origin xyz="0 0 0" rpy="0 0 0" />
    </xacro:sensor_l515> -->

</robot>